Workbook

Sheet Summary
B2: Therapy A | patient-based forecast
B3: Chinmayee Surwade | Launch forecast: January 2027 to December 2029
B5: Selected scenario | C5: =Assumptions!C3 -> Base
B7: Annual forecast | C7: 2027 | D7: 2028 | E7: 2029 | G7: Year | H7: INR crore
B8: Revenue (INR crore) | C8: =SUM('Patient forecast'!C29:F29)/10000000 -> 26.573163 | D8: =SUM('Patient forecast'!G29:J29)/10000000 -> 40.383105 | E8: =SUM('Patient forecast'!K29:N29)/10000000 -> 34.624707 | G8: 2027 | H8: =C8 -> 26.573163
B9: Therapy A new starts | C9: =SUM('Patient forecast'!C19:F19) -> 2575.2151 | D9: =SUM('Patient forecast'!G19:J19) -> 1609.5601 | E9: =SUM('Patient forecast'!K19:N19) -> 1181.8715 | G9: 2028 | H9: =D8 -> 40.383105
B10: Average active Therapy A patients | C10: =SUM('Patient forecast'!C24:F24)/12 -> 1107.2151 | D10: =SUM('Patient forecast'!G24:J24)/12 -> 1682.6294 | E10: =SUM('Patient forecast'!K24:N24)/12 -> 1442.6961 | G10: 2029 | H10: =E8 -> 34.624707
B11: Year-end active Therapy A patients | C11: ='Patient forecast'!F23 -> 1677.7142 | D11: ='Patient forecast'!J23 -> 1594.2065 | E11: ='Patient forecast'!N23 -> 1296.1211
B12: Therapy A share of new starts | C12: =IF(C13=0,0,C9/C13) -> 0.25 | D12: =IF(D13=0,0,D9/D13) -> 0.25 | E12: =IF(E13=0,0,E9/E13) -> 0.25
B13: All-therapy new starts | C13: =SUM('Patient forecast'!C16:F16) -> 10300.86 | D13: =SUM('Patient forecast'!G16:J16) -> 6438.2404 | E13: =SUM('Patient forecast'!K16:N16) -> 4727.4858
B15: Use: choose a case in Assumptions!C3, review patient flow, then read annual revenue. Inputs are illustrative; this is a modelling exercise, not a real product forecast.
B31: Market share means share of new treatment starts, not share of all patients currently receiving treatment. See the case study for the method, assumptions and interview explanation.

Sheet Assumptions
B2: Editable forecast assumptions
B3: Scenario (edit C3) | C3: Base | D3: Blue = editable input; green = cross-sheet formula; black = calculation. Change one scenario selector; all forecast outputs update.
B5: Quarter | C5: Q1 2027 | D5: Q2 2027 | E5: Q3 2027 | F5: Q4 2027 | G5: Q1 2028 | H5: Q2 2028 | I5: Q3 2028 | J5: Q4 2028 | K5: Q1 2029 | L5: Q2 2029 | M5: Q3 2029 | N5: Q4 2029
B7: Diagnosed fraction | Active | C7: =IF($C$3="Downside",IF(ISBLANK(C8),"",C8),IF($C$3="Base",IF(ISBLANK(C9),"",C9),IF(ISBLANK(C10),"",C10))) -> 0.7 | D7: =IF($C$3="Downside",IF(ISBLANK(D8),"",D8),IF($C$3="Base",IF(ISBLANK(D9),"",D9),IF(ISBLANK(D10),"",D10))) -> 0.7 | E7: =IF($C$3="Downside",IF(ISBLANK(E8),"",E8),IF($C$3="Base",IF(ISBLANK(E9),"",E9),IF(ISBLANK(E10),"",E10))) -> 0.7 | F7: =IF($C$3="Downside",IF(ISBLANK(F8),"",F8),IF($C$3="Base",IF(ISBLANK(F9),"",F9),IF(ISBLANK(F10),"",F10))) -> 0.7 | G7: =IF($C$3="Downside",IF(ISBLANK(G8),"",G8),IF($C$3="Base",IF(ISBLANK(G9),"",G9),IF(ISBLANK(G10),"",G10))) -> 0.7 | H7: =IF($C$3="Downside",IF(ISBLANK(H8),"",H8),IF($C$3="Base",IF(ISBLANK(H9),"",H9),IF(ISBLANK(H10),"",H10))) -> 0.7 | I7: =IF($C$3="Downside",IF(ISBLANK(I8),"",I8),IF($C$3="Base",IF(ISBLANK(I9),"",I9),IF(ISBLANK(I10),"",I10))) -> 0.7 | J7: =IF($C$3="Downside",IF(ISBLANK(J8),"",J8),IF($C$3="Base",IF(ISBLANK(J9),"",J9),IF(ISBLANK(J10),"",J10))) -> 0.7 | ... N7: =IF($C$3="Downside",IF(ISBLANK(N8),"",N8),IF($C$3="Base",IF(ISBLANK(N9),"",N9),IF(ISBLANK(N10),"",N10))) -> 0.7
B8: Downside | C8: 0.6 | D8: 0.6 | E8: 0.6 | F8: 0.6 | G8: 0.6 | H8: 0.6 | I8: 0.6 | J8: 0.6 | K8: 0.6 | L8: 0.6 | M8: 0.6 | N8: 0.6
B9: Base | C9: 0.7 | D9: 0.7 | E9: 0.7 | F9: 0.7 | G9: 0.7 | H9: 0.7 | I9: 0.7 | J9: 0.7 | K9: 0.7 | L9: 0.7 | M9: 0.7 | N9: 0.7
B10: Upside | C10: 0.8 | D10: 0.8 | E10: 0.8 | F10: 0.8 | G10: 0.8 | H10: 0.8 | I10: 0.8 | J10: 0.8 | K10: 0.8 | L10: 0.8 | M10: 0.8 | N10: 0.8
B12: Treated fraction of diagnosed | Active | C12: =IF($C$3="Downside",IF(ISBLANK(C13),"",C13),IF($C$3="Base",IF(ISBLANK(C14),"",C14),IF(ISBLANK(C15),"",C15))) -> 0.75 | D12: =IF($C$3="Downside",IF(ISBLANK(D13),"",D13),IF($C$3="Base",IF(ISBLANK(D14),"",D14),IF(ISBLANK(D15),"",D15))) -> 0.75 | E12: =IF($C$3="Downside",IF(ISBLANK(E13),"",E13),IF($C$3="Base",IF(ISBLANK(E14),"",E14),IF(ISBLANK(E15),"",E15))) -> 0.75 | F12: =IF($C$3="Downside",IF(ISBLANK(F13),"",F13),IF($C$3="Base",IF(ISBLANK(F14),"",F14),IF(ISBLANK(F15),"",F15))) -> 0.75 | G12: =IF($C$3="Downside",IF(ISBLANK(G13),"",G13),IF($C$3="Base",IF(ISBLANK(G14),"",G14),IF(ISBLANK(G15),"",G15))) -> 0.75 | H12: =IF($C$3="Downside",IF(ISBLANK(H13),"",H13),IF($C$3="Base",IF(ISBLANK(H14),"",H14),IF(ISBLANK(H15),"",H15))) -> 0.75 | I12: =IF($C$3="Downside",IF(ISBLANK(I13),"",I13),IF($C$3="Base",IF(ISBLANK(I14),"",I14),IF(ISBLANK(I15),"",I15))) -> 0.75 | J12: =IF($C$3="Downside",IF(ISBLANK(J13),"",J13),IF($C$3="Base",IF(ISBLANK(J14),"",J14),IF(ISBLANK(J15),"",J15))) -> 0.75 | ... N12: =IF($C$3="Downside",IF(ISBLANK(N13),"",N13),IF($C$3="Base",IF(ISBLANK(N14),"",N14),IF(ISBLANK(N15),"",N15))) -> 0.75
B13: Downside | C13: 0.65 | D13: 0.65 | E13: 0.65 | F13: 0.65 | G13: 0.65 | H13: 0.65 | I13: 0.65 | J13: 0.65 | K13: 0.65 | L13: 0.65 | M13: 0.65 | N13: 0.65
B14: Base | C14: 0.75 | D14: 0.75 | E14: 0.75 | F14: 0.75 | G14: 0.75 | H14: 0.75 | I14: 0.75 | J14: 0.75 | K14: 0.75 | L14: 0.75 | M14: 0.75 | N14: 0.75
B15: Upside | C15: 0.85 | D15: 0.85 | E15: 0.85 | F15: 0.85 | G15: 0.85 | H15: 0.85 | I15: 0.85 | J15: 0.85 | K15: 0.85 | L15: 0.85 | M15: 0.85 | N15: 0.85
B17: Second-line eligibility fraction | Active | C17: =IF($C$3="Downside",IF(ISBLANK(C18),"",C18),IF($C$3="Base",IF(ISBLANK(C19),"",C19),IF(ISBLANK(C20),"",C20))) -> 0.3 | D17: =IF($C$3="Downside",IF(ISBLANK(D18),"",D18),IF($C$3="Base",IF(ISBLANK(D19),"",D19),IF(ISBLANK(D20),"",D20))) -> 0.3 | E17: =IF($C$3="Downside",IF(ISBLANK(E18),"",E18),IF($C$3="Base",IF(ISBLANK(E19),"",E19),IF(ISBLANK(E20),"",E20))) -> 0.3 | F17: =IF($C$3="Downside",IF(ISBLANK(F18),"",F18),IF($C$3="Base",IF(ISBLANK(F19),"",F19),IF(ISBLANK(F20),"",F20))) -> 0.3 | G17: =IF($C$3="Downside",IF(ISBLANK(G18),"",G18),IF($C$3="Base",IF(ISBLANK(G19),"",G19),IF(ISBLANK(G20),"",G20))) -> 0.3 | H17: =IF($C$3="Downside",IF(ISBLANK(H18),"",H18),IF($C$3="Base",IF(ISBLANK(H19),"",H19),IF(ISBLANK(H20),"",H20))) -> 0.3 | I17: =IF($C$3="Downside",IF(ISBLANK(I18),"",I18),IF($C$3="Base",IF(ISBLANK(I19),"",I19),IF(ISBLANK(I20),"",I20))) -> 0.3 | J17: =IF($C$3="Downside",IF(ISBLANK(J18),"",J18),IF($C$3="Base",IF(ISBLANK(J19),"",J19),IF(ISBLANK(J20),"",J20))) -> 0.3 | ... N17: =IF($C$3="Downside",IF(ISBLANK(N18),"",N18),IF($C$3="Base",IF(ISBLANK(N19),"",N19),IF(ISBLANK(N20),"",N20))) -> 0.3
B18: Downside | C18: 0.25 | D18: 0.25 | E18: 0.25 | F18: 0.25 | G18: 0.25 | H18: 0.25 | I18: 0.25 | J18: 0.25 | K18: 0.25 | L18: 0.25 | M18: 0.25 | N18: 0.25
B19: Base | C19: 0.3 | D19: 0.3 | E19: 0.3 | F19: 0.3 | G19: 0.3 | H19: 0.3 | I19: 0.3 | J19: 0.3 | K19: 0.3 | L19: 0.3 | M19: 0.3 | N19: 0.3
B20: Upside | C20: 0.35 | D20: 0.35 | E20: 0.35 | F20: 0.35 | G20: 0.35 | H20: 0.35 | I20: 0.35 | J20: 0.35 | K20: 0.35 | L20: 0.35 | M20: 0.35 | N20: 0.35
B22: Quarterly uptake of available pool | Active | C22: =IF($C$3="Downside",IF(ISBLANK(C23),"",C23),IF($C$3="Base",IF(ISBLANK(C24),"",C24),IF(ISBLANK(C25),"",C25))) -> 0.18 | D22: =IF($C$3="Downside",IF(ISBLANK(D23),"",D23),IF($C$3="Base",IF(ISBLANK(D24),"",D24),IF(ISBLANK(D25),"",D25))) -> 0.18 | E22: =IF($C$3="Downside",IF(ISBLANK(E23),"",E23),IF($C$3="Base",IF(ISBLANK(E24),"",E24),IF(ISBLANK(E25),"",E25))) -> 0.18 | F22: =IF($C$3="Downside",IF(ISBLANK(F23),"",F23),IF($C$3="Base",IF(ISBLANK(F24),"",F24),IF(ISBLANK(F25),"",F25))) -> 0.18 | G22: =IF($C$3="Downside",IF(ISBLANK(G23),"",G23),IF($C$3="Base",IF(ISBLANK(G24),"",G24),IF(ISBLANK(G25),"",G25))) -> 0.18 | H22: =IF($C$3="Downside",IF(ISBLANK(H23),"",H23),IF($C$3="Base",IF(ISBLANK(H24),"",H24),IF(ISBLANK(H25),"",H25))) -> 0.18 | I22: =IF($C$3="Downside",IF(ISBLANK(I23),"",I23),IF($C$3="Base",IF(ISBLANK(I24),"",I24),IF(ISBLANK(I25),"",I25))) -> 0.18 | J22: =IF($C$3="Downside",IF(ISBLANK(J23),"",J23),IF($C$3="Base",IF(ISBLANK(J24),"",J24),IF(ISBLANK(J25),"",J25))) -> 0.18 | ... N22: =IF($C$3="Downside",IF(ISBLANK(N23),"",N23),IF($C$3="Base",IF(ISBLANK(N24),"",N24),IF(ISBLANK(N25),"",N25))) -> 0.18
B23: Downside | C23: 0.1 | D23: 0.1 | E23: 0.1 | F23: 0.1 | G23: 0.1 | H23: 0.1 | I23: 0.1 | J23: 0.1 | K23: 0.1 | L23: 0.1 | M23: 0.1 | N23: 0.1
B24: Base | C24: 0.18 | D24: 0.18 | E24: 0.18 | F24: 0.18 | G24: 0.18 | H24: 0.18 | I24: 0.18 | J24: 0.18 | K24: 0.18 | L24: 0.18 | M24: 0.18 | N24: 0.18
B25: Upside | C25: 0.26 | D25: 0.26 | E25: 0.26 | F25: 0.26 | G25: 0.26 | H25: 0.26 | I25: 0.26 | J25: 0.26 | K25: 0.26 | L25: 0.26 | M25: 0.26 | N25: 0.26
B27: Therapy A share of new starts | Active | C27: =IF($C$3="Downside",IF(ISBLANK(C28),"",C28),IF($C$3="Base",IF(ISBLANK(C29),"",C29),IF(ISBLANK(C30),"",C30))) -> 0.25 | D27: =IF($C$3="Downside",IF(ISBLANK(D28),"",D28),IF($C$3="Base",IF(ISBLANK(D29),"",D29),IF(ISBLANK(D30),"",D30))) -> 0.25 | E27: =IF($C$3="Downside",IF(ISBLANK(E28),"",E28),IF($C$3="Base",IF(ISBLANK(E29),"",E29),IF(ISBLANK(E30),"",E30))) -> 0.25 | F27: =IF($C$3="Downside",IF(ISBLANK(F28),"",F28),IF($C$3="Base",IF(ISBLANK(F29),"",F29),IF(ISBLANK(F30),"",F30))) -> 0.25 | G27: =IF($C$3="Downside",IF(ISBLANK(G28),"",G28),IF($C$3="Base",IF(ISBLANK(G29),"",G29),IF(ISBLANK(G30),"",G30))) -> 0.25 | H27: =IF($C$3="Downside",IF(ISBLANK(H28),"",H28),IF($C$3="Base",IF(ISBLANK(H29),"",H29),IF(ISBLANK(H30),"",H30))) -> 0.25 | I27: =IF($C$3="Downside",IF(ISBLANK(I28),"",I28),IF($C$3="Base",IF(ISBLANK(I29),"",I29),IF(ISBLANK(I30),"",I30))) -> 0.25 | J27: =IF($C$3="Downside",IF(ISBLANK(J28),"",J28),IF($C$3="Base",IF(ISBLANK(J29),"",J29),IF(ISBLANK(J30),"",J30))) -> 0.25 | ... N27: =IF($C$3="Downside",IF(ISBLANK(N28),"",N28),IF($C$3="Base",IF(ISBLANK(N29),"",N29),IF(ISBLANK(N30),"",N30))) -> 0.25
B28: Downside | C28: 0.15 | D28: 0.15 | E28: 0.15 | F28: 0.15 | G28: 0.15 | H28: 0.15 | I28: 0.15 | J28: 0.15 | K28: 0.15 | L28: 0.15 | M28: 0.15 | N28: 0.15
B29: Base | C29: 0.25 | D29: 0.25 | E29: 0.25 | F29: 0.25 | G29: 0.25 | H29: 0.25 | I29: 0.25 | J29: 0.25 | K29: 0.25 | L29: 0.25 | M29: 0.25 | N29: 0.25
B30: Upside | C30: 0.35 | D30: 0.35 | E30: 0.35 | F30: 0.35 | G30: 0.35 | H30: 0.35 | I30: 0.35 | J30: 0.35 | K30: 0.35 | L30: 0.35 | M30: 0.35 | N30: 0.35
B32: Quarterly treatment exit fraction | Active | C32: =IF($C$3="Downside",IF(ISBLANK(C33),"",C33),IF($C$3="Base",IF(ISBLANK(C34),"",C34),IF(ISBLANK(C35),"",C35))) -> 0.25 | D32: =IF($C$3="Downside",IF(ISBLANK(D33),"",D33),IF($C$3="Base",IF(ISBLANK(D34),"",D34),IF(ISBLANK(D35),"",D35))) -> 0.25 | E32: =IF($C$3="Downside",IF(ISBLANK(E33),"",E33),IF($C$3="Base",IF(ISBLANK(E34),"",E34),IF(ISBLANK(E35),"",E35))) -> 0.25 | F32: =IF($C$3="Downside",IF(ISBLANK(F33),"",F33),IF($C$3="Base",IF(ISBLANK(F34),"",F34),IF(ISBLANK(F35),"",F35))) -> 0.25 | G32: =IF($C$3="Downside",IF(ISBLANK(G33),"",G33),IF($C$3="Base",IF(ISBLANK(G34),"",G34),IF(ISBLANK(G35),"",G35))) -> 0.25 | H32: =IF($C$3="Downside",IF(ISBLANK(H33),"",H33),IF($C$3="Base",IF(ISBLANK(H34),"",H34),IF(ISBLANK(H35),"",H35))) -> 0.25 | I32: =IF($C$3="Downside",IF(ISBLANK(I33),"",I33),IF($C$3="Base",IF(ISBLANK(I34),"",I34),IF(ISBLANK(I35),"",I35))) -> 0.25 | J32: =IF($C$3="Downside",IF(ISBLANK(J33),"",J33),IF($C$3="Base",IF(ISBLANK(J34),"",J34),IF(ISBLANK(J35),"",J35))) -> 0.25 | ... N32: =IF($C$3="Downside",IF(ISBLANK(N33),"",N33),IF($C$3="Base",IF(ISBLANK(N34),"",N34),IF(ISBLANK(N35),"",N35))) -> 0.25
B33: Downside | C33: 0.3 | D33: 0.3 | E33: 0.3 | F33: 0.3 | G33: 0.3 | H33: 0.3 | I33: 0.3 | J33: 0.3 | K33: 0.3 | L33: 0.3 | M33: 0.3 | N33: 0.3
B34: Base | C34: 0.25 | D34: 0.25 | E34: 0.25 | F34: 0.25 | G34: 0.25 | H34: 0.25 | I34: 0.25 | J34: 0.25 | K34: 0.25 | L34: 0.25 | M34: 0.25 | N34: 0.25
B35: Upside | C35: 0.2 | D35: 0.2 | E35: 0.2 | F35: 0.2 | G35: 0.2 | H35: 0.2 | I35: 0.2 | J35: 0.2 | K35: 0.2 | L35: 0.2 | M35: 0.2 | N35: 0.2
B37: Net monthly price (INR) | Active | C37: =IF($C$3="Downside",IF(ISBLANK(C38),"",C38),IF($C$3="Base",IF(ISBLANK(C39),"",C39),IF(ISBLANK(C40),"",C40))) -> 20000 | D37: =IF($C$3="Downside",IF(ISBLANK(D38),"",D38),IF($C$3="Base",IF(ISBLANK(D39),"",D39),IF(ISBLANK(D40),"",D40))) -> 20000 | E37: =IF($C$3="Downside",IF(ISBLANK(E38),"",E38),IF($C$3="Base",IF(ISBLANK(E39),"",E39),IF(ISBLANK(E40),"",E40))) -> 20000 | F37: =IF($C$3="Downside",IF(ISBLANK(F38),"",F38),IF($C$3="Base",IF(ISBLANK(F39),"",F39),IF(ISBLANK(F40),"",F40))) -> 20000 | G37: =IF($C$3="Downside",IF(ISBLANK(G38),"",G38),IF($C$3="Base",IF(ISBLANK(G39),"",G39),IF(ISBLANK(G40),"",G40))) -> 20000 | H37: =IF($C$3="Downside",IF(ISBLANK(H38),"",H38),IF($C$3="Base",IF(ISBLANK(H39),"",H39),IF(ISBLANK(H40),"",H40))) -> 20000 | I37: =IF($C$3="Downside",IF(ISBLANK(I38),"",I38),IF($C$3="Base",IF(ISBLANK(I39),"",I39),IF(ISBLANK(I40),"",I40))) -> 20000 | J37: =IF($C$3="Downside",IF(ISBLANK(J38),"",J38),IF($C$3="Base",IF(ISBLANK(J39),"",J39),IF(ISBLANK(J40),"",J40))) -> 20000 | ... N37: =IF($C$3="Downside",IF(ISBLANK(N38),"",N38),IF($C$3="Base",IF(ISBLANK(N39),"",N39),IF(ISBLANK(N40),"",N40))) -> 20000
B38: Downside | C38: 18000 | D38: 18000 | E38: 18000 | F38: 18000 | G38: 18000 | H38: 18000 | I38: 18000 | J38: 18000 | K38: 18000 | L38: 18000 | M38: 18000 | N38: 18000
B39: Base | C39: 20000 | D39: 20000 | E39: 20000 | F39: 20000 | G39: 20000 | H39: 20000 | I39: 20000 | J39: 20000 | K39: 20000 | L39: 20000 | M39: 20000 | N39: 20000
B40: Upside | C40: 22000 | D40: 22000 | E40: 22000 | F40: 22000 | G40: 22000 | H40: 22000 | I40: 22000 | J40: 22000 | K40: 22000 | L40: 22000 | M40: 22000 | N40: 22000
B42: Annual incidence growth | Active | C42: =IF($C$3="Downside",IF(ISBLANK(C43),"",C43),IF($C$3="Base",IF(ISBLANK(C44),"",C44),IF(ISBLANK(C45),"",C45))) -> 0.02 | D42: =IF($C$3="Downside",IF(ISBLANK(D43),"",D43),IF($C$3="Base",IF(ISBLANK(D44),"",D44),IF(ISBLANK(D45),"",D45))) -> 0.02 | E42: =IF($C$3="Downside",IF(ISBLANK(E43),"",E43),IF($C$3="Base",IF(ISBLANK(E44),"",E44),IF(ISBLANK(E45),"",E45))) -> 0.02 | F42: =IF($C$3="Downside",IF(ISBLANK(F43),"",F43),IF($C$3="Base",IF(ISBLANK(F44),"",F44),IF(ISBLANK(F45),"",F45))) -> 0.02 | G42: =IF($C$3="Downside",IF(ISBLANK(G43),"",G43),IF($C$3="Base",IF(ISBLANK(G44),"",G44),IF(ISBLANK(G45),"",G45))) -> 0.02 | H42: =IF($C$3="Downside",IF(ISBLANK(H43),"",H43),IF($C$3="Base",IF(ISBLANK(H44),"",H44),IF(ISBLANK(H45),"",H45))) -> 0.02 | I42: =IF($C$3="Downside",IF(ISBLANK(I43),"",I43),IF($C$3="Base",IF(ISBLANK(I44),"",I44),IF(ISBLANK(I45),"",I45))) -> 0.02 | J42: =IF($C$3="Downside",IF(ISBLANK(J43),"",J43),IF($C$3="Base",IF(ISBLANK(J44),"",J44),IF(ISBLANK(J45),"",J45))) -> 0.02 | ... N42: =IF($C$3="Downside",IF(ISBLANK(N43),"",N43),IF($C$3="Base",IF(ISBLANK(N44),"",N44),IF(ISBLANK(N45),"",N45))) -> 0.02
B43: Downside | C43: 0.01 | D43: 0.01 | E43: 0.01 | F43: 0.01 | G43: 0.01 | H43: 0.01 | I43: 0.01 | J43: 0.01 | K43: 0.01 | L43: 0.01 | M43: 0.01 | N43: 0.01
B44: Base | C44: 0.02 | D44: 0.02 | E44: 0.02 | F44: 0.02 | G44: 0.02 | H44: 0.02 | I44: 0.02 | J44: 0.02 | K44: 0.02 | L44: 0.02 | M44: 0.02 | N44: 0.02
B45: Upside | C45: 0.03 | D45: 0.03 | E45: 0.03 | F45: 0.03 | G45: 0.03 | H45: 0.03 | I45: 0.03 | J45: 0.03 | K45: 0.03 | L45: 0.03 | M45: 0.03 | N45: 0.03
B48: Quarter length (months) | C48: 3
B49: New-start timing within quarter | C49: 0.5
B50: Exit timing within quarter | C50: 0.5
B52: Second-line eligibility is a simplified aggregate fraction of treated diagnoses, not a clinical transition model. Change quarter-specific case inputs to model launch ramps.
B54: Timing = fraction of quarter with treatment: 50% for new starts; 50% for exiting opening patients. New starters cannot exit until the next quarter.
...

Sheet Patient forecast
B2: Patient flow and commercial forecast
B3: Selected scenario | C3: =Assumptions!C3 -> Base
B5: Metric | C5: Q1 2027 | D5: Q2 2027 | E5: Q3 2027 | F5: Q4 2027 | G5: Q1 2028 | H5: Q2 2028 | I5: Q3 2028 | J5: Q4 2028 | K5: Q1 2029 | L5: Q2 2029 | M5: Q3 2029 | N5: Q4 2029
B7: Incident patients this quarter | C7: ='Source data'!$D$17/4*(1+Assumptions!C42)^0 -> 5090 | D7: ='Source data'!$D$17/4*(1+Assumptions!D42)^0 -> 5090 | E7: ='Source data'!$D$17/4*(1+Assumptions!E42)^0 -> 5090 | F7: ='Source data'!$D$17/4*(1+Assumptions!F42)^0 -> 5090 | G7: ='Source data'!$D$17/4*(1+Assumptions!G42)^1 -> 5191.8 | H7: ='Source data'!$D$17/4*(1+Assumptions!H42)^1 -> 5191.8 | I7: ='Source data'!$D$17/4*(1+Assumptions!I42)^1 -> 5191.8 | J7: ='Source data'!$D$17/4*(1+Assumptions!J42)^1 -> 5191.8 | K7: ='Source data'!$D$17/4*(1+Assumptions!K42)^2 -> 5295.636 | L7: ='Source data'!$D$17/4*(1+Assumptions!L42)^2 -> 5295.636 | M7: ='Source data'!$D$17/4*(1+Assumptions!M42)^2 -> 5295.636 | N7: ='Source data'!$D$17/4*(1+Assumptions!N42)^2 -> 5295.636
B8: Launch prevalent pool (one-time) | C8: ='Source data'!$D$16 -> 105400 | D8: =0 -> 0 | E8: =0 -> 0 | F8: =0 -> 0 | G8: =0 -> 0 | H8: =0 -> 0 | I8: =0 -> 0 | J8: =0 -> 0 | K8: =0 -> 0 | ... N8: =0 -> 0
B9: Patients available for eligibility screening | C9: =C7+C8 -> 110490 | D9: =D7+D8 -> 5090 | E9: =E7+E8 -> 5090 | F9: =F7+F8 -> 5090 | G9: =G7+G8 -> 5191.8 | H9: =H7+H8 -> 5191.8 | I9: =I7+I8 -> 5191.8 | J9: =J7+J8 -> 5191.8 | ... N9: =N7+N8 -> 5295.636
B10: Diagnosed patients | C10: =C9*Assumptions!C7 -> 77343 | D10: =D9*Assumptions!D7 -> 3563 | E10: =E9*Assumptions!E7 -> 3563 | F10: =F9*Assumptions!F7 -> 3563 | G10: =G9*Assumptions!G7 -> 3634.26 | H10: =H9*Assumptions!H7 -> 3634.26 | I10: =I9*Assumptions!I7 -> 3634.26 | J10: =J9*Assumptions!J7 -> 3634.26 | ... N10: =N9*Assumptions!N7 -> 3706.9452
B11: Treated diagnoses | C11: =C10*Assumptions!C12 -> 58007.25 | D11: =D10*Assumptions!D12 -> 2672.25 | E11: =E10*Assumptions!E12 -> 2672.25 | F11: =F10*Assumptions!F12 -> 2672.25 | G11: =G10*Assumptions!G12 -> 2725.695 | H11: =H10*Assumptions!H12 -> 2725.695 | I11: =I10*Assumptions!I12 -> 2725.695 | J11: =J10*Assumptions!J12 -> 2725.695 | ... N11: =N10*Assumptions!N12 -> 2780.2089
B12: New second-line eligible patients | C12: =C11*Assumptions!C17 -> 17402.175 | D12: =D11*Assumptions!D17 -> 801.675 | E12: =E11*Assumptions!E17 -> 801.675 | F12: =F11*Assumptions!F17 -> 801.675 | G12: =G11*Assumptions!G17 -> 817.7085 | H12: =H11*Assumptions!H17 -> 817.7085 | I12: =I11*Assumptions!I17 -> 817.7085 | J12: =J11*Assumptions!J17 -> 817.7085 | ... N12: =N11*Assumptions!N17 -> 834.06267
B14: Opening eligible patients awaiting uptake | C14: =0 -> 0 | D14: =C17 -> 14269.783 | E14: =D17 -> 12358.596 | F14: =E17 -> 10791.422 | G14: =F17 -> 9506.3397 | H14: =G17 -> 8465.7195 | I14: =H17 -> 7612.411 | J14: =I17 -> 6912.698 | K14: =J17 -> 6338.9333 | ... N14: =M17 -> 5199.7156
B15: Available second-line eligible pool | C15: =C14+C12 -> 17402.175 | D15: =D14+D12 -> 15071.458 | E15: =E14+E12 -> 13160.271 | F15: =F14+F12 -> 11593.097 | G15: =G14+G12 -> 10324.048 | H15: =H14+H12 -> 9283.428 | I15: =I14+I12 -> 8430.1195 | J15: =J14+J12 -> 7730.4065 | ... N15: =N14+N12 -> 6033.7782
B16: All-therapy starts this quarter | C16: =C15*Assumptions!C22 -> 3132.3915 | D16: =D15*Assumptions!D22 -> 2712.8625 | E16: =E15*Assumptions!E22 -> 2368.8488 | F16: =F15*Assumptions!F22 -> 2086.7575 | G16: =G15*Assumptions!G22 -> 1858.3287 | H16: =H15*Assumptions!H22 -> 1671.017 | I16: =I15*Assumptions!I22 -> 1517.4215 | J16: =J15*Assumptions!J22 -> 1391.4732 | ... N16: =N15*Assumptions!N22 -> 1086.0801
B17: Closing eligible patients awaiting uptake | C17: =C15-C16 -> 14269.783 | D17: =D15-D16 -> 12358.596 | E17: =E15-E16 -> 10791.422 | F17: =F15-F16 -> 9506.3397 | G17: =G15-G16 -> 8465.7195 | H17: =H15-H16 -> 7612.411 | I17: =I15-I16 -> 6912.698 | J17: =J15-J16 -> 6338.9333 | ... N17: =N15-N16 -> 4947.6982
B19: Therapy A new starts | C19: =C16*Assumptions!C27 -> 783.09787 | D19: =D16*Assumptions!D27 -> 678.21563 | E19: =E16*Assumptions!E27 -> 592.21219 | F19: =F16*Assumptions!F27 -> 521.68937 | G19: =G16*Assumptions!G27 -> 464.58217 | H19: =H16*Assumptions!H27 -> 417.75426 | I19: =I16*Assumptions!I27 -> 379.35538 | J19: =J16*Assumptions!J27 -> 347.86829 | ... N19: =N16*Assumptions!N27 -> 271.52002
B20: Other-therapy new starts | C20: =C16-C19 -> 2349.2936 | D20: =D16-D19 -> 2034.6469 | E20: =E16-E19 -> 1776.6366 | F20: =F16-F19 -> 1565.0681 | G20: =G16-G19 -> 1393.7465 | H20: =H16-H19 -> 1253.2628 | I20: =I16-I19 -> 1138.0661 | J20: =J16-J19 -> 1043.6049 | ... N20: =N16-N19 -> 814.56006
B21: Opening active Therapy A patients | C21: =0 -> 0 | D21: =C23 -> 783.09787 | E21: =D23 -> 1265.539 | F21: =E23 -> 1541.3665 | G21: =F23 -> 1677.7142 | H21: =G23 -> 1722.8678 | I21: =H23 -> 1709.9051 | J21: =I23 -> 1661.7842 | K21: =J23 -> 1594.2065 | ... N21: =M23 -> 1366.1348
B22: Therapy A treatment exits | C22: =C21*Assumptions!C32 -> 0 | D22: =D21*Assumptions!D32 -> 195.77447 | E22: =E21*Assumptions!E32 -> 316.38476 | F22: =F21*Assumptions!F32 -> 385.34162 | G22: =G21*Assumptions!G32 -> 419.42856 | H22: =H21*Assumptions!H32 -> 430.71696 | I22: =I21*Assumptions!I32 -> 427.47629 | J22: =J21*Assumptions!J32 -> 415.44606 | ... N22: =N21*Assumptions!N32 -> 341.53371
B23: Closing active Therapy A patients | C23: =C21+C19-C22 -> 783.09787 | D23: =D21+D19-D22 -> 1265.539 | E23: =E21+E19-E22 -> 1541.3665 | F23: =F21+F19-F22 -> 1677.7142 | G23: =G21+G19-G22 -> 1722.8678 | H23: =H21+H19-H22 -> 1709.9051 | I23: =I21+I19-I22 -> 1661.7842 | J23: =J21+J19-J22 -> 1594.2065 | ... N23: =N21+N19-N22 -> 1296.1211
B24: Therapy A patient-months | C24: =(C21-C22)*Assumptions!$C$48+C22*Assumptions!$C$48*Assumptions!$C$50+C19*Assumptions!$C$48*Assumptions!$C$49 -> 1174.6468 | D24: =(D21-D22)*Assumptions!$C$48+D22*Assumptions!$C$48*Assumptions!$C$50+D19*Assumptions!$C$48*Assumptions!$C$49 -> 3072.9554 | E24: =(E21-E22)*Assumptions!$C$48+E22*Assumptions!$C$48*Assumptions!$C$50+E19*Assumptions!$C$48*Assumptions!$C$49 -> 4210.3583 | F24: =(F21-F22)*Assumptions!$C$48+F22*Assumptions!$C$48*Assumptions!$C$50+F19*Assumptions!$C$48*Assumptions!$C$49 -> 4828.6211 | G24: =(G21-G22)*Assumptions!$C$48+G22*Assumptions!$C$48*Assumptions!$C$50+G19*Assumptions!$C$48*Assumptions!$C$49 -> 5100.8731 | H24: =(H21-H22)*Assumptions!$C$48+H22*Assumptions!$C$48*Assumptions!$C$50+H19*Assumptions!$C$48*Assumptions!$C$49 -> 5149.1595 | I24: =(I21-I22)*Assumptions!$C$48+I22*Assumptions!$C$48*Assumptions!$C$50+I19*Assumptions!$C$48*Assumptions!$C$49 -> 5057.5341 | J24: =(J21-J22)*Assumptions!$C$48+J22*Assumptions!$C$48*Assumptions!$C$50+J19*Assumptions!$C$48*Assumptions!$C$49 -> 4883.986 | ... N24: =(N21-N22)*Assumptions!$C$48+N22*Assumptions!$C$48*Assumptions!$C$50+N19*Assumptions!$C$48*Assumptions!$C$49 -> 3993.384
B25: Average active Therapy A patients | C25: =C24/Assumptions!$C$48 -> 391.54894 | D25: =D24/Assumptions!$C$48 -> 1024.3185 | E25: =E24/Assumptions!$C$48 -> 1403.4528 | F25: =F24/Assumptions!$C$48 -> 1609.5404 | G25: =G24/Assumptions!$C$48 -> 1700.291 | H25: =H24/Assumptions!$C$48 -> 1716.3865 | I25: =I24/Assumptions!$C$48 -> 1685.8447 | J25: =J24/Assumptions!$C$48 -> 1627.9953 | ... N25: =N24/Assumptions!$C$48 -> 1331.128
B26: Therapy A share of new starts | C26: =IF(C16=0,0,C19/C16) -> 0.25 | D26: =IF(D16=0,0,D19/D16) -> 0.25 | E26: =IF(E16=0,0,E19/E16) -> 0.25 | F26: =IF(F16=0,0,F19/F16) -> 0.25 | G26: =IF(G16=0,0,G19/G16) -> 0.25 | H26: =IF(H16=0,0,H19/H16) -> 0.25 | I26: =IF(I16=0,0,I19/I16) -> 0.25 | J26: =IF(J16=0,0,J19/J16) -> 0.25 | ... N26: =IF(N16=0,0,N19/N16) -> 0.25
B28: Net monthly price (INR) | C28: =Assumptions!C37 -> 20000 | D28: =Assumptions!D37 -> 20000 | E28: =Assumptions!E37 -> 20000 | F28: =Assumptions!F37 -> 20000 | G28: =Assumptions!G37 -> 20000 | H28: =Assumptions!H37 -> 20000 | I28: =Assumptions!I37 -> 20000 | J28: =Assumptions!J37 -> 20000 | ... N28: =Assumptions!N37 -> 20000
B29: Therapy A revenue (INR) | C29: =C24*C28 -> 23492936 | D29: =D24*D28 -> 61459107 | E29: =E24*E28 -> 84207165 | F29: =F24*F28 -> 96572421 | G29: =G24*G28 -> 1.0201746e+08 | H29: =H24*H28 -> 1.0298319e+08 | I29: =I24*I28 -> 1.0115068e+08 | J29: =J24*J28 -> 97679721 | ... N29: =N24*N28 -> 79867680
B30: All-therapy new starts, cumulative | C30: =SUM($C16:C16) -> 3132.3915 | D30: =SUM($C16:D16) -> 5845.254 | E30: =SUM($C16:E16) -> 8214.1028 | F30: =SUM($C16:F16) -> 10300.86 | G30: =SUM($C16:G16) -> 12159.189 | H30: =SUM($C16:H16) -> 13830.206 | I30: =SUM($C16:I16) -> 15347.628 | J30: =SUM($C16:J16) -> 16739.101 | ... N30: =SUM($C16:N16) -> 21466.587
B31: Therapy A starts, cumulative | C31: =SUM($C19:C19) -> 783.09787 | D31: =SUM($C19:D19) -> 1461.3135 | E31: =SUM($C19:E19) -> 2053.5257 | F31: =SUM($C19:F19) -> 2575.2151 | G31: =SUM($C19:G19) -> 3039.7972 | H31: =SUM($C19:H19) -> 3457.5515 | I31: =SUM($C19:I19) -> 3836.9069 | J31: =SUM($C19:J19) -> 4184.7752 | ... N31: =SUM($C19:N19) -> 5366.6466
B33: Eligible-pool reconciliation difference | C33: =C14+C12-C16-C17 -> 0 | D33: =D14+D12-D16-D17 -> 0 | E33: =E14+E12-E16-E17 -> 0 | F33: =F14+F12-F16-F17 -> 0 | G33: =G14+G12-G16-G17 -> 0 | H33: =H14+H12-H16-H17 -> 0 | I33: =I14+I12-I16-I17 -> 0 | J33: =J14+J12-J16-J17 -> 0 | ... N33: =N14+N12-N16-N17 -> 0
B34: Active-patient reconciliation difference | C34: =C21+C19-C22-C23 -> 0 | D34: =D21+D19-D22-D23 -> 0 | E34: =E21+E19-E22-E23 -> 0 | F34: =F21+F19-F22-F23 -> 0 | G34: =G21+G19-G22-G23 -> 0 | H34: =H21+H19-H22-H23 -> 0 | I34: =I21+I19-I22-I23 -> 0 | J34: =J21+J19-J22-J23 -> 0 | ... N34: =N21+N19-N22-N23 -> 0
B35: Starts split reconciliation difference | C35: =C16-C19-C20 -> 0 | D35: =D16-D19-D20 -> 0 | E35: =E16-E19-E20 -> 0 | F35: =F16-F19-F20 -> 0 | G35: =G16-G19-G20 -> 0 | H35: =H16-H19-H20 -> 0 | I35: =I16-I19-I20 -> 0 | J35: =J16-J19-J20 -> 0 | ... N35: =N16-N19-N20 -> 0
B36: Negative stock / flow count | C36: =COUNTIF(C14:C25,"<0") -> 0 | D36: =COUNTIF(D14:D25,"<0") -> 0 | E36: =COUNTIF(E14:E25,"<0") -> 0 | F36: =COUNTIF(F14:F25,"<0") -> 0 | G36: =COUNTIF(G14:G25,"<0") -> 0 | H36: =COUNTIF(H14:H25,"<0") -> 0 | I36: =COUNTIF(I14:I25,"<0") -> 0 | J36: =COUNTIF(J14:J25,"<0") -> 0 | ... N36: =COUNTIF(N14:N25,"<0") -> 0
B37: Input assumption issues count | C37: =COUNTBLANK(Assumptions!C7)+COUNTBLANK(Assumptions!C12)+COUNTBLANK(Assumptions!C17)+COUNTBLANK(Assumptions!C22)+COUNTBLANK(Assumptions!C27)+COUNTBLANK(Assumptions!C32)+COUNTBLANK(Assumptions!C37)+COUNTBLANK(Assumptions!C42)+IF(OR(Assumptions!C7<0,Assumptions!C7>1,Assumptions!C12<0,Assumptions!C12>1,Assumptions!C17<0,Assumptions!C17>1,Assumptions!C22<0,Assumptions!C22>1,Assumptions!C27<0,Assumptions!C27>1,Assumptions!C32<0,Assumptions!C32>1,Assumptions!C37<0,Assumptions!C42<=-1,Assumptions!$C$48<=0,Assumptions!$C$49<0,Assumptions!$C$49>1,Assumptions!$C$50<0,Assumptions!$C$50>1),1,0) -> 0 | D37: =COUNTBLANK(Assumptions!D7)+COUNTBLANK(Assumptions!D12)+COUNTBLANK(Assumptions!D17)+COUNTBLANK(Assumptions!D22)+COUNTBLANK(Assumptions!D27)+COUNTBLANK(Assumptions!D32)+COUNTBLANK(Assumptions!D37)+COUNTBLANK(Assumptions!D42)+IF(OR(Assumptions!D7<0,Assumptions!D7>1,Assumptions!D12<0,Assumptions!D12>1,Assumptions!D17<0,Assumptions!D17>1,Assumptions!D22<0,Assumptions!D22>1,Assumptions!D27<0,Assumptions!D27>1,Assumptions!D32<0,Assumptions!D32>1,Assumptions!D37<0,Assumptions!D42<=-1,Assumptions!$C$48<=0,Assumptions!$C$49<0,Assumptions!$C$49>1,Assumptions!$C$50<0,Assumptions!$C$50>1),1,0) -> 0 | E37: =COUNTBLANK(Assumptions!E7)+COUNTBLANK(Assumptions!E12)+COUNTBLANK(Assumptions!E17)+COUNTBLANK(Assumptions!E22)+COUNTBLANK(Assumptions!E27)+COUNTBLANK(Assumptions!E32)+COUNTBLANK(Assumptions!E37)+COUNTBLANK(Assumptions!E42)+IF(OR(Assumptions!E7<0,Assumptions!E7>1,Assumptions!E12<0,Assumptions!E12>1,Assumptions!E17<0,Assumptions!E17>1,Assumptions!E22<0,Assumptions!E22>1,Assumptions!E27<0,Assumptions!E27>1,Assumptions!E32<0,Assumptions!E32>1,Assumptions!E37<0,Assumptions!E42<=-1,Assumptions!$C$48<=0,Assumptions!$C$49<0,Assumptions!$C$49>1,Assumptions!$C$50<0,Assumptions!$C$50>1),1,0) -> 0 | F37: =COUNTBLANK(Assumptions!F7)+COUNTBLANK(Assumptions!F12)+COUNTBLANK(Assumptions!F17)+COUNTBLANK(Assumptions!F22)+COUNTBLANK(Assumptions!F27)+COUNTBLANK(Assumptions!F32)+COUNTBLANK(Assumptions!F37)+COUNTBLANK(Assumptions!F42)+IF(OR(Assumptions!F7<0,Assumptions!F7>1,Assumptions!F12<0,Assumptions!F12>1,Assumptions!F17<0,Assumptions!F17>1,Assumptions!F22<0,Assumptions!F22>1,Assumptions!F27<0,Assumptions!F27>1,Assumptions!F32<0,Assumptions!F32>1,Assumptions!F37<0,Assumptions!F42<=-1,Assumptions!$C$48<=0,Assumptions!$C$49<0,Assumptions!$C$49>1,Assumptions!$C$50<0,Assumptions!$C$50>1),1,0) -> 0 | G37: =COUNTBLANK(Assumptions!G7)+COUNTBLANK(Assumptions!G12)+COUNTBLANK(Assumptions!G17)+COUNTBLANK(Assumptions!G22)+COUNTBLANK(Assumptions!G27)+COUNTBLANK(Assumptions!G32)+COUNTBLANK(Assumptions!G37)+COUNTBLANK(Assumptions!G42)+IF(OR(Assumptions!G7<0,Assumptions!G7>1,Assumptions!G12<0,Assumptions!G12>1,Assumptions!G17<0,Assumptions!G17>1,Assumptions!G22<0,Assumptions!G22>1,Assumptions!G27<0,Assumptions!G27>1,Assumptions!G32<0,Assumptions!G32>1,Assumptions!G37<0,Assumptions!G42<=-1,Assumptions!$C$48<=0,Assumptions!$C$49<0,Assumptions!$C$49>1,Assumptions!$C$50<0,Assumptions!$C$50>1),1,0) -> 0 | H37: =COUNTBLANK(Assumptions!H7)+COUNTBLANK(Assumptions!H12)+COUNTBLANK(Assumptions!H17)+COUNTBLANK(Assumptions!H22)+COUNTBLANK(Assumptions!H27)+COUNTBLANK(Assumptions!H32)+COUNTBLANK(Assumptions!H37)+COUNTBLANK(Assumptions!H42)+IF(OR(Assumptions!H7<0,Assumptions!H7>1,Assumptions!H12<0,Assumptions!H12>1,Assumptions!H17<0,Assumptions!H17>1,Assumptions!H22<0,Assumptions!H22>1,Assumptions!H27<0,Assumptions!H27>1,Assumptions!H32<0,Assumptions!H32>1,Assumptions!H37<0,Assumptions!H42<=-1,Assumptions!$C$48<=0,Assumptions!$C$49<0,Assumptions!$C$49>1,Assumptions!$C$50<0,Assumptions!$C$50>1),1,0) -> 0 | I37: =COUNTBLANK(Assumptions!I7)+COUNTBLANK(Assumptions!I12)+COUNTBLANK(Assumptions!I17)+COUNTBLANK(Assumptions!I22)+COUNTBLANK(Assumptions!I27)+COUNTBLANK(Assumptions!I32)+COUNTBLANK(Assumptions!I37)+COUNTBLANK(Assumptions!I42)+IF(OR(Assumptions!I7<0,Assumptions!I7>1,Assumptions!I12<0,Assumptions!I12>1,Assumptions!I17<0,Assumptions!I17>1,Assumptions!I22<0,Assumptions!I22>1,Assumptions!I27<0,Assumptions!I27>1,Assumptions!I32<0,Assumptions!I32>1,Assumptions!I37<0,Assumptions!I42<=-1,Assumptions!$C$48<=0,Assumptions!$C$49<0,Assumptions!$C$49>1,Assumptions!$C$50<0,Assumptions!$C$50>1),1,0) -> 0 | J37: =COUNTBLANK(Assumptions!J7)+COUNTBLANK(Assumptions!J12)+COUNTBLANK(Assumptions!J17)+COUNTBLANK(Assumptions!J22)+COUNTBLANK(Assumptions!J27)+COUNTBLANK(Assumptions!J32)+COUNTBLANK(Assumptions!J37)+COUNTBLANK(Assumptions!J42)+IF(OR(Assumptions!J7<0,Assumptions!J7>1,Assumptions!J12<0,Assumptions!J12>1,Assumptions!J17<0,Assumptions!J17>1,Assumptions!J22<0,Assumptions!J22>1,Assumptions!J27<0,Assumptions!J27>1,Assumptions!J32<0,Assumptions!J32>1,Assumptions!J37<0,Assumptions!J42<=-1,Assumptions!$C$48<=0,Assumptions!$C$49<0,Assumptions!$C$49>1,Assumptions!$C$50<0,Assumptions!$C$50>1),1,0) -> 0 | ... N37: =COUNTBLANK(Assumptions!N7)+COUNTBLANK(Assumptions!N12)+COUNTBLANK(Assumptions!N17)+COUNTBLANK(Assumptions!N22)+COUNTBLANK(Assumptions!N27)+COUNTBLANK(Assumptions!N32)+COUNTBLANK(Assumptions!N37)+COUNTBLANK(Assumptions!N42)+IF(OR(Assumptions!N7<0,Assumptions!N7>1,Assumptions!N12<0,Assumptions!N12>1,Assumptions!N17<0,Assumptions!N17>1,Assumptions!N22<0,Assumptions!N22>1,Assumptions!N27<0,Assumptions!N27>1,Assumptions!N32<0,Assumptions!N32>1,Assumptions!N37<0,Assumptions!N42<=-1,Assumptions!$C$48<=0,Assumptions!$C$49<0,Assumptions!$C$49>1,Assumptions!$C$50<0,Assumptions!$C$50>1),1,0) -> 0
B39: Counts are expected aggregate patients, so decimals are retained. Revenue is patient-months × net monthly price; it excludes tax, distribution costs and profit.

Sheet Source data
B2: Synthetic market inputs
B3: Fictional Indication X and Therapy A. All numbers are invented for an Excel portfolio exercise, not clinical or market evidence.
B5: Record ID | C5: Segment | D5: Population | E5: Prevalence | F5: Annual incidence | G5: Include | H5: Review reason
B6: S01 | C6: North | D6: 20000000 | E6: 0.001 | F6: 0.0002 | G6: 1 | H6: Unique valid segment
B7: S02 | C7: South | D7: 25000000 | E7: 0.0012 | F7: 0.00022 | G7: 1 | H7: Unique valid segment
B8: S03 | C8: East | D8: 18000000 | E8: 0.0009 | F8: 0.00018 | G8: 1 | H8: Unique valid segment
B9: S04 | C9: West | D9: 22000000 | E9: 0.0011 | F9: 0.00021 | G9: 1 | H9: Unique valid segment
B10: S05 | C10: Central | D10: 15000000 | E10: 0.001 | F10: 0.0002 | G10: 1 | H10: Unique valid segment
B11: S03 | C11: East duplicate | D11: 18000000 | E11: 0.0009 | F11: 0.00018 | G11: 0 | H11: Duplicate ID; exclude
B12: S06 | C12: Unspecified | E12: 0.001 | F12: 0.0002 | G12: 0 | H12: Missing population; exclude
B15: Included population | D15: =SUMPRODUCT(D6:D12,G6:G12) -> 100000000
B16: Prevalent patients at launch | D16: =SUMPRODUCT(D6:D12,E6:E12,G6:G12) -> 105400
B17: Annual incident patients | D17: =SUMPRODUCT(D6:D12,F6:F12,G6:G12) -> 20360
B19: Data preparation: retain the original rows; exclude duplicate S03 and the missing-population row using Include = 0. Recheck these flags when replacing data.
B21: Population is a launch-market denominator. Prevalence defines the one-time launch pool; incidence supplies new quarterly patients. No identifiable patient data is used.
